I'm sorry, but an uncaught exception occurred.

While running game code:
  File "game/script.rpy", line 30, in script
    e "You've created a new Ren'Py game."
Exception: Sayer 'e' is not defined.

-- Full Traceback ------------------------------------------------------------

Full traceback:
  File "game/script.rpy", line 30, in script
    e "You've created a new Ren'Py game."
  File "C:\Users\yamin\Documents\renpy-8.3.2-sdk\renpy\ast.py", line 2573, in execute
    Say.execute(self)
  File "C:\Users\yamin\Documents\renpy-8.3.2-sdk\renpy\ast.py", line 575, in execute
    who = eval_who(self.who, self.who_fast)
  File "C:\Users\yamin\Documents\renpy-8.3.2-sdk\renpy\ast.py", line 464, in eval_who
    raise Exception("Sayer '%s' is not defined." % who)
Exception: Sayer 'e' is not defined.

Windows-10-10.0.22631 AMD64
Ren'Py 8.3.2.24090902
cybergarde part1 1.0
Tue Dec 17 14:39:53 2024
